<?xml version="1.0"?>

<robot xmlns:xacro="http://www.ros.org/wiki/xacro" name='jetbot'>

	<xacro:property name="robot_name" value="$(arg robot_name)"/>
	<xacro:include filename="inertial_macros.xacro"/>
	<xacro:include filename="lidar.xacro"/>
	<xacro:include filename="camera.xacro"/>
	<xacro:include filename="gazebo_controllers.xacro"/>
	<xacro:include filename="ros2_controllers.xacro"/>
	


<!--Materials-->

	<material name="black">
		<color rgba="0 0 0 1"/>
	</material>

	<material name="blue">
		<color rgba="0 0 1 1"/>
	</material>

	<material name="green">
		<color rgba="0 1 0 1"/>
	</material>

  
	<link name="${robot_name}/base_link"></link>
	
<!--Chassis"-->

	<joint name="${robot_name}/chassis_joint" type="fixed">
  		<origin xyz="0.0 0.0 0.0325" rpy="0 0 0"/>
  		<parent link="${robot_name}/base_link"/>
  		<child link="${robot_name}/chassis"/>
	</joint>
  
    <link name='${robot_name}/chassis'>
		<xacro:inertial_cylinder mass="2.8943" radius="0.106625" length="0.01">
			<origin xyz="0.0 0.0 0.015" rpy="0 0 0"/>
		</xacro:inertial_cylinder>
		<!--Main Parts-->
    	<visual>
    		<origin xyz="0.0 0.0 0.015" rpy="0 0 0"/>
  			<geometry>
  				<cylinder radius="0.106625" length="0.01"/>
  			</geometry>
			<material name="green"/>
		</visual>
		<collision>
    		<origin xyz="0.0 0.0 0.015" rpy="0 0 0"/>
  			<geometry>
  				<cylinder radius="0.106625" length="0.01"/>
  			</geometry>
		</collision>
		<visual>
			<origin xyz="0.0 0.0 0.063675" rpy="0 0 0"/>
  			<geometry>
          		<box size="0.1 0.08 0.08935"/>
        	</geometry>
			<material name="black"/>
		</visual>
		<collision>
			<origin xyz="0.0 0.0 0.063675" rpy="0 0 0"/>
  			<geometry>
          		<box size="0.1 0.08 0.08935"/>
        	</geometry>
			<material name="black"/>
		</collision>
		<!--Antennas-->
		<visual>
			<origin xyz="-0.06 -0.06 0.084" rpy="0 0 0"/>
  			<geometry>
          		<cylinder radius="0.003" length="0.13639"/>
        	</geometry>
			<material name="black"/>
		</visual>
		<visual>
			<origin xyz="-0.06 0.06 0.084" rpy="0 0 0"/>
  			<geometry>
          		<cylinder radius="0.003" length="0.13639"/>
        	</geometry>
			<material name="black"/>
		</visual>
		<!--Camera Handle-->
		<visual>
			<origin xyz="0.09315 0.0 0.04222" rpy="0 0 0"/>
  			<geometry>
          		<box size="0.01 0.02 0.04444"/>
        	</geometry>
			<material name="green"/>
		</visual>
	</link>

	<gazebo reference="${robot_name}/chassis">
		<material>Gazebo/Green</material>
	</gazebo>
		

<!--Left Wheel-->

	<joint name="${robot_name}/leftWheel_joint" type="continuous">
  		<parent link="${robot_name}/chassis"/>
  		<child link="${robot_name}/leftWheel"/>
		<origin xyz="0.0 0.09315 0.0" rpy="-1.5707 0 0"/>
		<axis xyz="0 0 1"/>
	</joint>
  

    <link name='${robot_name}/leftWheel'>
		<xacro:inertial_cylinder mass="0.031" radius="0.0325" length="0.027">
			<origin xyz="0 0 0" rpy="0 0 0"/>
		</xacro:inertial_cylinder>
    	<visual>			
  			<geometry>
  				<cylinder radius="0.0325" length="0.027"/>
  			</geometry>
			<material name="blue"/>
		</visual>
		<collision>			
  			<geometry>
  				<sphere radius="0.0325"/>
  			</geometry>
		</collision>
	</link>

	<gazebo reference="${robot_name}/leftWheel">
		<material>Gazebo/Blue</material>
		<mu1 value="1.0"/>
		<mu2 value="1.0"/>
	</gazebo>

<!--Right Wheel-->

	<joint name="${robot_name}/rightWheel_joint" type="continuous">
  		<parent link="${robot_name}/chassis"/>
  		<child link="${robot_name}/rightWheel"/>
		<origin xyz="0.0 -0.09315 0.0" rpy="1.5707 0 0"/>
		<axis xyz="0 0 -1"/>
	</joint>
  

    <link name='${robot_name}/rightWheel'>
		<xacro:inertial_cylinder mass="0.031" radius="0.0325" length="0.027">
			<origin xyz="0 0 0" rpy="0 0 0"/>
		</xacro:inertial_cylinder>
    	<visual>			
  			<geometry>
  				<cylinder radius="0.0325" length="0.027"/>
  			</geometry>
			<material name="blue"/>
		</visual>
		<collision>			
  			<geometry>
  				<sphere radius="0.0325"/>
  			</geometry>
		</collision>
	</link>

	<gazebo reference="${robot_name}/rightWheel">
		<material>Gazebo/Blue</material>
		<mu1 value="1.0"/>
		<mu2 value="1.0"/>
	</gazebo>

<!--Front Caster-->

	<joint name="${robot_name}/frontCaster_joint" type="fixed">
  		<parent link="${robot_name}/chassis"/>
  		<child link="${robot_name}/frontCaster"/>
		<origin xyz="0.09315 0.0 0.0" rpy="0 0 0"/>
	</joint>
  

    <link name='${robot_name}/frontCaster'>
		<xacro:inertial_sphere mass="0.022" radius="0.022">
			<origin xyz="0 0 -0.01" rpy="0 0 0"/>
		</xacro:inertial_sphere>
    	<visual>	
			<origin xyz="0 0 -0.01" rpy="0 0 0"/>		
  			<geometry>
  				<sphere radius="0.022"/>
  			</geometry>
			<material name="black"/>
		</visual>
		<collision>		
			<origin xyz="0 0 -0.01" rpy="0 0 0"/>	
  			<geometry>
  				<sphere radius="0.022"/>
  			</geometry>
		</collision>
	</link>

	<gazebo reference="${robot_name}/frontCaster">
		<material>Gazebo/Black</material>
		<mu1 value="0.01"/>
		<mu2 value="0.01"/>
	</gazebo>

<!--Rear Caster-->

	<joint name="${robot_name}/rearCaster_joint" type="fixed">
  		<parent link="${robot_name}/chassis"/>
  		<child link="${robot_name}/rearCaster"/>
		<origin xyz="-0.09315 0.0 0.0" rpy="0 0 0"/>
	</joint>
  

    <link name='${robot_name}/rearCaster'>
		<xacro:inertial_sphere mass="0.022" radius="0.022">
			<origin xyz="0 0 -0.01" rpy="0 0 0"/>
		</xacro:inertial_sphere>
    	<visual>			
			<origin xyz="0 0 -0.01" rpy="0 0 0"/>
  			<geometry>
  				<sphere radius="0.022"/>
  			</geometry>
			<material name="black"/>
		</visual>
		<collision>			
			<origin xyz="0 0 -0.01" rpy="0 0 0"/>
  			<geometry>
  				<sphere radius="0.022"/>
  			</geometry>
		</collision>
	</link>

	<gazebo reference="${robot_name}/rearCaster">
		<material>Gazebo/Black</material>
		<mu1 value="0.01"/>
		<mu2 value="0.01"/>
	</gazebo>
</robot>
  	
